Workbook
Name チェック内容: #REF!
Name チェック内容: #REF!

Sheet Histories
B2: 共通情報 | F2: プロジェクト名 | N2: =Header!N2 -> Fresher - small project | AR2: 作成者 | AV2: =Header!AV2 -> Huỳnh Lê An
F3: システム名 | N3: =Header!N3 -> Hotel Maneger | AR3: 作成日付 | AV3: =Header!AV3 -> 45840
F4: 工程名 | N4: =Header!N4 -> Detail Design | AR4: バージョン | AV4: =Header!AP4 -> 0
F5: ドキュメントID | AR5: 更新者
F6: ドキュメント名 | N6: =Header!N6 -> Detail Design Screen | AR6: 更新日付 | AV6: =Header!AV6 -> 45840
B7: 詳細情報 | F7: 画面ID
F8: 画面名称 | N8: =Header!N8 -> List Role
F9: 概要 | N9: =Header!N9 -> List Role, including some information and delete button.
B12: 作成・更新履歴
B13: 日付 | F13: Rev.No | I13: 対象シート名 | P13: 内容 | BC13: 担当者
B14: 45810 | F14: 1 | I14: List roles | P14: Display all roles | BC14: Huỳnh Lê An

Sheet Layout
B2: 共通情報 | F2: プロジェクト名 | N2: =Header!N2 -> Fresher - small project | AR2: 作成者 | AV2: =Header!AV2 -> Huỳnh Lê An
F3: システム名 | N3: =Header!N3 -> Hotel Maneger | AR3: 作成日付 | AV3: =Header!AV3 -> 45840
F4: 工程名 | N4: =Header!N4 -> Detail Design | AR4: バージョン | AV4: =Header!AV4 -> 0
F5: ドキュメントID | AR5: 更新者
F6: ドキュメント名 | N6: =Header!N6 -> Detail Design Screen | AR6: 更新日付 | AV6: =Header!AV6 -> 45840
B7: 詳細情報 | F7: 画面ID
F8: 画面名称 | N8: =Header!N8 -> List Role
F9: 概要 | N9: =Header!N9 -> List Role, including some information and delete button.
B13: Main view:

Sheet field definition
B2: 共通情報 | F2: プロジェクト名 | N2: =Header!N2 -> Fresher - small project | AR2: 作成者 | AV2: =Header!AV2 -> Huỳnh Lê An
F3: システム名 | N3: =Header!N3 -> Hotel Maneger | AR3: 作成日付 | AV3: =Header!AV3 -> 45840
F4: 工程名 | N4: =Header!N4 -> Detail Design | AR4: バージョン | AV4: =Header!AV4 -> 0
F5: ドキュメントID | AR5: 更新者
F6: ドキュメント名 | N6: =Header!N6 -> Detail Design Screen | AR6: 更新日付 | AV6: =Header!AV6 -> 45840
B7: 詳細情報 | F7: 画面ID
F8: 画面名称 | N8: =Header!N8 -> List Role
F9: 概要 | N9: =Header!N9 -> List Role, including some information and delete button.
B12: 項目定義
B13: No | D13: 項目-Field | R13: 必須 required | T13: 種類 type | X13: I/O | Z13: 初期値 | AD13: Table | AJ13: カラム名 Column name | AR13: 項目説明・備考
B14: メイン | E14: Main
B15: 1 | D15: Name (EN) | R15: 〇 | T15: textbox | X15: I | Z15: - | AD15: hotels | AJ15: name_en | AR15: the english name of hotel
B16: 2 | D16: Name (JP) | R16: 〇 | T16: textbox | X16: I | Z16: - | AD16: hotels | AJ16: name_jp | AR16: the japanese name of hotel
B17: 3 | D17: Telephone | R17: 〇 | T17: textbox | X17: I | Z17: - | AD17: hotels | AJ17: telephone
B18: 4 | D18: Fax | R18: - | T18: textbox | X18: I | Z18: - | AD18: hotels | AJ18: fax
B19: 5 | D19: Company Name | R19: 〇 | T19: textbox | X19: I | Z19: - | AD19: hotels | AJ19: company_name | AR19: the company which owns the hotel
B20: 6 | D20: Tax Code | R20: - | T20: textbox | X20: I | Z20: - | AD20: hotels | AJ20: tax_code
B21: 7 | D21: Email | R21: 〇 | T21: textbox | X21: I | Z21: - | AD21: hotels | AJ21: email
B22: 8 | D22: Address 1 | R22: 〇 | T22: textbox | X22: I | Z22: - | AD22: hotels | AJ22: address_1
B23: 9 | D23: Address 2 | R23: - | T23: textbox | X23: I | Z23: - | AD23: hotels | AJ23: address_2
B24: 10 | D24: Save | R24: - | T24: Button | X24: - | Z24: - | AD24: - | AJ24: - | AR24: click: save the change information
B25: 11 | D25: Back | R25: - | T25: Button | X25: - | Z25: - | AD25: - | AJ25: - | AR25: click: go back into previous page
B26: お知らせ一覧 | E26: Main | H26: List Notification
B27: 1 | D27: Success message | R27: - | T27: Literal | X27: O | Z27: - | AR27: when hotel information is changed successfully
B28: 1 | D28: Fail message | R28: - | T28: Literal | X28: O | Z28: - | AR28: when hotel information change failed

Sheet Outline of processing
B2: 共通情報 | F2: プロジェクト名 | N2: =Header!N2 -> Fresher - small project | AR2: 作成者 | AV2: =Header!AV2 -> Huỳnh Lê An
F3: システム名 | N3: =Header!N3 -> Hotel Maneger | AR3: 作成日付 | AV3: =Header!AV3 -> 45840
F4: 工程名 | N4: =Header!N4 -> Detail Design | AR4: バージョン | AV4: =Header!AV4 -> 0
F5: ドキュメントID | AR5: 更新者
F6: ドキュメント名 | N6: =Header!N6 -> Detail Design Screen | AR6: 更新日付 | AV6: =Header!AV6 -> 45840
B7: 詳細情報 | F7: 画面ID
F8: 画面名称 | N8: =Header!N8 -> List Role
F9: 概要 | N9: =Header!N9 -> List Role, including some information and delete button.
B12: Event | F12: Check the permission of current user
B13: Trigger | F13: Click button edit hotel or double click on row contains hotel information
B14: Luồng xử lí | F14: Check the user's permissions, then navigate to the page based on their permissions and the software's policies
B15: Note | F15: -
B16: ＜処理概要＞
C17: 1. | D17: Check the permission of current user
D19: 1.1. | F19: If the user lacks permission, redirect to the 403 Unauthorize page
D21: 1.2. | F21: If user is Admin, or user is Owner of this hotel, can go to this page.
B23: Event | F23: Initialize displayed
B24: Trigger | F24: Transition from other screen
B25: Processing flow | F25: Display user management screen
B26: Note | F26: -
B27: ＜処理概要＞
C28: 1 | D28: Display items on the screen according to the screen layout
D30: 1.1. | F30: Display the selected hotel's information based on data from the database.
I32: Use table | O32: hotels, cities
I33: Search criteria | O33: Display only the information of the selected hotel. | AK33: The value of the `id` field matches the value of the passed parameter.
I34: Sort | O34: -
D36: 1.2. | F36: List all cities, the current city of hotel will be selected
D38: 1.3. | F38: Disable Save Hotel button
B40: Event | F40: Handle edit hotel process
B41: Trigger | F41: Click the edit button
B42: Processing flow | F42: Validate user input data, then processd with editing the selected hotel
B43: Note | F43: -
B44: ＜処理概要＞
C45: 1 | D45: Handle edit hotel process
D46: Proceed to edit the selected hotel
E48: 1.1 | G48: Perform validation on user input values (refer to the input definition sheet).
G50: 1.1.1 | K50: Terminate processing and display error messages on the screen if validation fails for any input fields.
G52: 1.1.2. | K52: If fails for other reasons, then displaying error message on the head of the page.
E54: 1.2 | G54: Successfully edit the selected hotel, display success message and disble button Save.
B56: Event | F56: Cancel the editing process for the selected hotel.
...

Sheet input definition
B2: 共通情報 | F2: プロジェクト名 | N2: =Header!N2 -> Fresher - small project | AR2: 作成者 | AV2: =Header!AV2 -> Huỳnh Lê An
F3: システム名 | N3: =Header!N3 -> Hotel Maneger | AR3: 作成日付 | AV3: =Header!AV3 -> 45840
F4: 工程名 | AR4: バージョン | AV4: =Header!AV4 -> 0
F5: ドキュメントID | AR5: 更新者
F6: ドキュメント名 | N6: =Header!N6 -> Detail Design Screen | AR6: 更新日付 | AV6: =Header!AV6 -> 45840
B7: 詳細情報 | F7: 画面ID
F8: 画面名称 | N8: =Header!N8 -> List Role
F9: 概要 | N9: =Header!N9 -> List Role, including some information and delete button.
B12: 入力項目チェック定義 Definition input field check
B13: No | D13: 項目名 Field name | M13: 共通チェック Common check | AD13: 個別チェック内容 Nội dung check | AM13: 個別エラーメッセージ Error Message | BA13: 備考 Note
M14: チェックID/チェック内容 Check ID/ Nội dung check | X14: パラメータ Parameter
B15: 1 | D15: name en | M15: CK001/Required fields | X15: - | AD15: - | AM15: =SUBSTITUTE(SUBSTITUTE(VLOOKUP(M15, Message!A2:F25, 6, FALSE), "[Item name]", D15), "[item name]", D15) -> *The name en field is required.
M16: CK015/Unique data field | X16: - | AD16: - | AM16: =SUBSTITUTE(SUBSTITUTE(VLOOKUP(M16,Message!A2:F25, 6, FALSE), "[Item name]", D15), "[item name]", D15) -> *The name en has already been taken.
M17: CK002/Maximum number of digits (<=n) | X17: n:255 | AD17: - | AM17: =SUBSTITUTE(SUBSTITUTE(VLOOKUP(M17, Message!A2:F25, 6, FALSE), "[Item name]", D15), "[Range value]", MID(X17, FIND(":", X17) + 1, LEN(X17))) -> *The name en must not be greater than 255 characters.
M18: CK009/Alphanumeric characters | X18: - | AD18: - | AM18: =SUBSTITUTE(SUBSTITUTE(VLOOKUP(M18, Message!A2:F25, 6, FALSE), "[Item name]", D15), "[item name]", D15) -> *The name en must only contain letters, numbers and space.
B19: 2 | D19: name jp | M19: CK001/Required fields | X19: - | AD19: - | AM19: =SUBSTITUTE(SUBSTITUTE(VLOOKUP(M19, Message!A2:F25, 6, FALSE), "[Item name]", D19), "[item name]", D19) -> *The name jp field is required.
M20: CK015/Unique data field | X20: - | AD20: - | AM20: =SUBSTITUTE(SUBSTITUTE(VLOOKUP(M20, Message!A2:F25, 6, FALSE), "[Item name]", D19), "[item name]", D19) -> *The name jp has already been taken.
M21: CK002/Maximum number of digits (<=n) | X21: n:255 | AD21: - | AM21: =SUBSTITUTE(SUBSTITUTE(VLOOKUP(M21,Message!A2:F25, 6, FALSE), "[Item name]", D19), "[Range value]", MID(X21, FIND(":", X21) + 1, LEN(X21))) -> *The name jp must not be greater than 255 characters.
M22: CK009/Alphanumeric characters | X22: - | AD22: - | AM22: =SUBSTITUTE(SUBSTITUTE(VLOOKUP(M22, Message!A2:F25, 6, FALSE), "[Item name]", D19), "[Item name]", D19) -> *The name jp must only contain letters, numbers and space.
B23: 3 | D23: city id | M23: CK001/Required fields | X23: - | AD23: - | AM23: =SUBSTITUTE(SUBSTITUTE(VLOOKUP(M23, Message!A2:F25, 6, FALSE), "[Item name]", D23), "[item name]", D23) -> *The city id field is required.
M24: CK025/ID exists in database | X24: Database:City | AD24: - | AM24: =SUBSTITUTE(SUBSTITUTE(VLOOKUP(M24, [1]Message!A2:F27, 6, FALSE), "[Item name]", D23), "[Database]", MID(X24, SEARCH(":", X24) + 1, LEN(X24) - SEARCH(":", X24))) -> *The city id value is not exists in database City.
M25: CK011/Numbers only | X25: - | AD25: - | AM25: =SUBSTITUTE(SUBSTITUTE(VLOOKUP(M25, Message!A3:F26, 6, FALSE), "[Item name]", D23), "[Item name]", D23) -> *The city id must be a number.
B26: 4 | D26: hotel code | M26: CK001/Required fields | X26: - | AD26: - | AM26: =SUBSTITUTE(SUBSTITUTE(VLOOKUP(M26, Message!A2:F25, 6, FALSE), "[Item name]", D26), "[item name]", D26) -> *The hotel code field is required.
M27: CK006/Number of specified digits matches | X27: n:6 | AD27: - | AM27: =SUBSTITUTE(SUBSTITUTE(VLOOKUP(M27, Message!A2:F25, 6, FALSE), "[Item name]", D26), "[Range value]", MID(X27, FIND(":", X27) + 1, LEN(X27))) -> *The hotel code must be 6 characters.
M28: CK010/Alphanumeric characters only | X28: - | AD28: - | AM28: =SUBSTITUTE(SUBSTITUTE(VLOOKUP(M28,Message!A2:F25, 6, FALSE), "[Item name]", D26), "[item name]", D26) -> *The hotel code must only contain letters and numbers.
M29: CK015/Unique data field | X29: - | AD29: - | AM29: =SUBSTITUTE(SUBSTITUTE(VLOOKUP(M29, Message!A13:F36, 6, FALSE), "[Item name]", D26), "[item name]", D26) -> *The hotel code has already been taken.
B30: 5 | D30: company name | M30: CK001/Required fields | X30: - | AD30: - | AM30: =SUBSTITUTE(SUBSTITUTE(VLOOKUP(M30, Message!A2:F25, 6, FALSE), "[Item name]", D30), "[item name]", D30) -> *The company name field is required.
M31: CK002/Maximum number of digits (<=n) | X31: n:255 | AD31: - | AM31: =SUBSTITUTE(SUBSTITUTE(VLOOKUP(M31, Message!A2:F25, 6, FALSE), "[Item name]", D30), "[Range value]", MID(X31, FIND(":", X31) + 1, LEN(X31))) -> *The company name must not be greater than 255 characters.
B32: 6 | D32: email | M32: CK001/Required fields | X32: - | AD32: - | AM32: =SUBSTITUTE( SUBSTITUTE(VLOOKUP(M32,Message!A2:F25, 6, FALSE), "[Item name]",D32), "[item name]",D32) -> *The email field is required.
M33: CK002/Maximum number of digits (<=n) | X33: n:255 | AD33: - | AM33: =SUBSTITUTE(SUBSTITUTE(VLOOKUP(M33, [1]Message!A2:F25, 6, FALSE), "[Item name]", D32), "[Range value]", MID(X33, FIND(":", X33) + 1, LEN(X33))) -> *The email must not be greater than 255 characters.
M34: CK013/Email address format | X34: - | AD34: - | AM34: =SUBSTITUTE(SUBSTITUTE(VLOOKUP(M34, Message!A2:F25, 6, FALSE), "[Item name]", D32), "[item name]", D32) -> *The email field must be a valid email address.
B35: 7 | D35: telephone | M35: CK001/Required fields | X35: - | AD35: - | AM35: =SUBSTITUTE(SUBSTITUTE(VLOOKUP(M35, Message!A2:F25, 6, FALSE), "[Item name]", D35), "[item name]", D35) -> *The telephone field is required.
M36: CK022/Fax, Telephone | X36: n:255 | AD36: - | AM36: =SUBSTITUTE(SUBSTITUTE(VLOOKUP(M36, Message!A2:F25, 6, FALSE), "[Item name]", D35), "[item name]", D35) -> *The telephone format is invalid.
B37: 8 | D37: fax | M37: CK002/Maximum number of digits (<=n) | X37: n:255 | AD37: - | AM37: =SUBSTITUTE(SUBSTITUTE(VLOOKUP(M37, [1]Message!A2:F25, 6, FALSE), "[Item name]", D37), "[Range value]", MID(X37, FIND(":", X37) + 1, LEN(X37))) -> *The fax must not be greater than 255 characters.
M38: CK022/Fax, Telephone | X38: - | AD38: - | AM38: =SUBSTITUTE( SUBSTITUTE(VLOOKUP(M38, Message!A3:F30, 6, FALSE), "[Item name]",D37), "[item name]",D37) -> *The fax format is invalid.
B39: 9 | D39: tax code | M39: CK001/Required fields | X39: - | AD39: - | AM39: =SUBSTITUTE(SUBSTITUTE(VLOOKUP(M39, Message!A2:F25, 6, FALSE), "[Item name]", D39), "[item name]", D39) -> *The tax code field is required.
M40: CK002/Maximum number of digits (<=n) | X40: n:13 | AD40: - | AM40: =SUBSTITUTE(SUBSTITUTE(VLOOKUP(M40, [1]Message!A2:F26, 6, FALSE), "[Item name]", D39), "[Range value]", MID(X40, FIND(":", X40) + 1, LEN(X40))) -> *The tax code must not be greater than 13 characters.
M41: CK004/Lower limit of digits (>=n) | X41: n:10 | AD41: - | AM41: =SUBSTITUTE(SUBSTITUTE(VLOOKUP(M41, [1]Message!A3:F27, 6, FALSE), "[Item name]", D40), "[Range value]", MID(X41, FIND(":", X41) + 1, LEN(X41))) -> *The must be at least 10 characters.
M42: CK023/Contains numbers only | X42: - | AD42: - | AM42: =SUBSTITUTE(SUBSTITUTE(VLOOKUP(M42, [1]Message!A11:F34, 6, FALSE), "[Item name]", D39), "[item name]", D39) -> *The tax code format is invalid.
B43: 10 | D43: adress 1 | M43: CK001/Required fields | X43: - | AD43: - | AM43: =SUBSTITUTE(SUBSTITUTE(VLOOKUP(M43, Message!A2:F25, 6, FALSE), "[Item name]", D43), "[item name]", D43) -> *The adress 1 field is required.
...

Sheet Message
A1: Check ID/Check Name | B1: Check ID | C1: Check Name | D1: Check Type | E1: Validation conditions | F1: Message
A2: CK001/Required fields | B2: CK001 | C2: Required fields | D2: - | E2: If a required field is not filled in, an error occurs. | F2: *The [Item name] field is required.
A3: CK002/Maximum number of digits (<=n) | B3: CK002 | C3: Maximum number of digits (<=n) | D3: Check maximum number of digits | E3: The number of bytes of the input value is checked, and if it exceeds the value specified for each item, an error is returned. | F3: *The [Item name] must not be greater than [Range value] characters.
A4: CK003/Maximum number of digits (<n) | B4: CK003 | C4: Maximum number of digits (<n) | F4: *The [Item name] must be within [Range value] characters.
A5: CK004/Lower limit of digits (>=n) | B5: CK004 | C5: Lower limit of digits (>=n) | D5: Check the minimum number of digits | E5: The number of bytes of the input value is checked, and if it is less than the number specified for each item, an error occurs. | F5: *The [Item name] must be at least [Range value] characters.
A6: CK005/Specified number of digits (within range) | B6: CK005 | C6: Specified number of digits (within range) | D6: Upper and lower limit check | E6: If the number of digits is not the specified number, an error occurs. | F6: *The [Item name] must be from the [Range Value From] digits to the [Range Value To] digits.
A7: CK006/Number of specified digits matches | B7: CK006 | C7: Number of specified digits matches | D7: Check specified digit | E7: If the number of digits is not the specified number, an error occurs. | F7: *The [Item name] must be [Range value] characters.
A8: CK007/Prohibited characters (space, tab) | B8: CK007 | C8: Prohibited characters (space, tab) | D8: Space/Tab Check | E8: If the input value contains spaces or tabs, an error occurs. | F8: *The [Item name] format is invalid.
A9: CK008/Prohibited characters (except /) | B9: CK008 | C9: Prohibited characters (except /) | D9: others | E9: If "/" or "|" is entered in the input value, an error will occur. | F9: *The [Item name] format is invalid.
A10: CK009/Alphanumeric characters | B10: CK009 | C10: Alphanumeric characters only | D10: Alphanumeric check | E10: Check whether the input string is alphanumeric or not, and if it is not, an error occurs. | F10: *The [Item name] must only contain letters, numbers and space.
A11: CK010/Alphanumeric characters only | B11: CK010 | C11: Alphanumeric characters only | D11: Alphanumeric symbol check | E11: Check whether the input string is alphanumeric and contains space or not, and if it is not, an error will occur. | F11: *The [Item name] must only contain letters and numbers.
A12: CK011/Numbers only | B12: CK011 | C12: Numbers only | D12: Number Check | E12: Check whether the input string is a number, and if it is not a number, an error occurs. | F12: *The [Item name] must be a number.
A13: CK012/Required selection | B13: CK012 | C13: Required selection | D13: Date Check | E13: If no selection is made for a required item, an error occurs. | F13: *[Item name] is not selected.
A14: CK013/Email address format | B14: CK013 | C14: Email address format | D14: email address | E14: Check whether the input string is in the specified format, and if it is not in the specified format, an error occurs. | F14: *The [Item name] field must be a valid email address.
A15: CK014/Both items do not match | B15: CK014 | C15: Both items do not match | D15: Discrepancy Check | E15: If the same content is entered in a location where the same item should not be set, an error will occur. | F15: *Confirm [Item name] not correct.
A16: CK015/Unique data field | B16: CK015 | C16: Duplicate data field | D16: email address | E16: The entered string is checked, and if the value is already registered, an error is generated. | F16: *The [Item name] has already been taken.
A17: CK016/Missing input fields | B17: CK016 | C17: Missing input fields | D17: - | E17: If any field is left unfilled where all related fields must be filled in, an error will occur. | F17: *[Item name] has not been entered.
A18: CK017/Insufficient input fields (multiple input fields) | B18: CK017 | C18: Insufficient input fields (multiple input fields) | D18: - | F18: *Please enter all items in [Item name].
A19: CK018/Specified extension | B19: CK018 | C19: Specified extension | D19: - | E19: If an extension other than the specified one is entered, an error will occur. | F19: The permitted format for [Item name] is [Extension].
A20: CK019/File exists | B20: CK019 | C20: File exists | D20: - | E20: If the specified file does not exist, an error occurs. | F20: *[Input value] not found.
A21: CK020/Upload execution status | B21: CK020 | C21: Upload execution status | D21: Check if it is running | E21: If the file upload has not been performed, an error occurs. | F21: *Please upload [Item name].
A22: CK021/Upload size | B22: CK021 | C22: Upload size | D22: Size Check | E22: If the specified file size is larger than the specified size, an error occurs. | F22: *The size of [Item name] is not bigger than [Size].
A23: CK022/Fax, Telephone | B23: CK022 | C23: Check fax, telephone | D23: Fax, telephone check | E23: Input value should only contain number, space and '-' | F23: *The [Item name] format is invalid.
A24: CK023/Contains numbers only | B24: CK23 | C24: Check string only contain numbers | D24: Check string | E24: If the value contains characters other than numeric characters. | F24: *The [Item name] format is invalid.
A25: CK024/Format password | B25: CK24 | C25: Check format password | D25: Check format password | E25: The password must contain at least one letter, one number, and one special character. | F25: *The [Item name] format is invalid.
A26: CK025/others | B26: CK025 | C26: Others | F26: Stated in the remarks

Sheet Header
B2: 共通情報 | F2: プロジェクト名 | N2: Fresher - small project | AR2: 作成者 | AV2: Huỳnh Lê An
F3: システム名 | N3: Hotel Maneger | AR3: 作成日付 | AV3: 45840
F4: 工程名 | N4: Detail Design | AR4: バージョン | AV4: =Header!AP4 -> 0
F5: ドキュメントID | AR5: 更新者
F6: ドキュメント名 | N6: Detail Design Screen | AR6: 更新日付 | AV6: 45840
B7: 詳細情報 | F7: 画面ID
F8: 画面名称 | N8: List Role
F9: 概要 | N9: List Role, including some information and delete button.
